Workbook

Sheet 문서번호1
C1: 작업자 : | P1: 조사자: | U1: 새움터
A3: 사업장명 : | C3: 유성기업 영동공장
U4: 문서번호 | AA4: 1
A5: 근골격계 유해요인조사 관리카드(1/3)
A6: 평가구분 | D6: 정기조사 | L6: ( | AB6: [ | AD6: ])
A7: 평가대상 | C7: 평가번호 | K7: 부서명 | T7: 작업명
C8: 44935 | K8: 생산1팀 | T8: CTB
A9: 전체작업조건 | C9: 1일작업시간 | K9: 1일생산량 | T9: 작업일수 | Y9: 작업순환주기 | AH9: `
C11: 작업빈도 | K11: 상시작업 | T11: 간헐작업
C12: 고용형태 | J12: 정규직 | P12: 임시직 | U12: 일용직 | Z12: 기타
C13: 직무자율성 | J13: 작업속도와 휴식 등 여유시간 스스로 조절 가능
J14: 라인작업은 아니나 정해진 휴식시간 외에는 작업을 해야 함
J15: 라인작업이며 정해진 작업속도에 맞추어야 함
A16: 요소작업명 | C16: 작업내용 | U16: 관련사진
A17: 1 | B17: 작업1
A18: 2 | B18: 작업2
A19: 기타 위험요인 | D19: 소음 | G19: 온열 | J19: 화상 | M19: 분진 | P19: 사고성재해 | U19: 스트레스 | Y19: 기타 | AA19: [ | AD19: ]
A20: 부담부위 | D20: 손/손목 | H20: 팔꿈치/아래팔 | N20: 어깨/위팔 | S20: 목 | U20: 허리/고관절 | Z20: 무릎/발목
A21: 작업조건 변화 (최근3년) | C21: 작업시간(특근 등) | K21: 변화없음 | P21: 변화있음 | T21: [ | AD21: ]
C22: 작업속도 | K22: 변화없음 | P22: 변화있음 | T22: [ | AD22: ]
C23: 인력 | K23: 변화없음 | P23: 변화있음 | T23: [ | AD23: ]
C24: 작업량(일의종류) | K24: 변화없음 | P24: 변화있음 | T24: [ | AD24: ]
C25: 작업 설비 | K25: 변화없음 | P25: 변화있음 | T25: [ | AD25: ]
A26: 참조

Sheet 문서번호2(1)
T1: 문서번호 | V1: 2
A2: 근골격계 유해요인조사 관리카드(2/3)
A3: 평가 대상 | B3: 부서명 | J3: 작업명 | T3: 요소작업명
B4: =문서번호1!K8 -> 생산1팀 | J4: =문서번호1!T8 -> CTB | T4: =문서번호1!B17 -> 작업1
A5: 작업 특성 | B5: ◆ 공구무게 | H5: ( | K5: )kg
B6: ◆ 중량물 무게 | H6: ( | K6: )kg | L6: × | M6: 빈도 1일 | P6: ( | S6: ) | T6: 회
B7: ◆ 밀고당기기 | H7: ( | K7: )kgf | L7: × | M7: 빈도 1일 | P7: ( | S7: ) | T7: 회
B8: ◆ 전신진동발생원 | H8: ( | K8: ) | M8: 1일 평균 | P8: ( | S8: ) | T8: 시간
A9: 위험 요인 | B9: 위험요인 노출특성 (신체 부위별 자세/힘의사용/정적/반복/진동/압박/충격 등 부가점수 포함 최고 점수 : 7점)
A10: 손/손목 | B10: 자세[5] | T10: 힘[+1] | U10: 정적/반복[+1] | W10: 점수[7]
B11: 굴곡/신전[3] | J11: 외전/내전[+2] | T11: 취급물 중량 손가락>1kg 또는 손>2kg(1) | U11: 1분이상 정적자세(1) | V11: 분당 4회이상 반복(1) | W11: =IF(X11<8,X11,7) -> 1 | X11: =MAX(B14,F14)+IF((J14+O14)>=2,2,J14+O14)+T14+MAX(U14,V14)+V15 -> 1
B12: 굴곡 | F12: 신전 | J12: 내전[2] | O12: 외전[2]
B14: =IF(B13<15,1,IF(B13<45,2,3)) -> 1 | F14: =IF(F13<15,1,IF(F13<45,2,3)) -> 1 | J14: =IF(J13<15,0,IF(J13<30,1,2)) -> 0 | O14: =IF(O13<15,0,IF(O13<30,1,2)) -> 0 | T14: 0 | U14: 0 | V14: 0
B15: ◆ 부가점수 (각 +1) : | V15: =COUNTIF(X16:Z18,TRUE) -> 0
C16: [공구 1kg 이상] | J16: [공구 2kg 이상] | Q16: [공구진동] | X16: FALSE | Y16: FALSE | Z16: FALSE
C17: [손가락 쥐기/집기] | J17: [과도한 손가락 신전] | Q17: [접촉 압박/충격] | X17: FALSE | Y17: FALSE | Z17: FALSE
C18: [미끄러운 장갑 착용] | J18: [손을 망치처럼 사용] | X18: FALSE | Y18: FALSE
A19: 팔꿈치 /아래팔 | B19: 자세[5] | T19: 힘[+1] | U19: 정적/반복[+1] | W19: 점수[7]
B20: 굴곡[3] | J20: 회내전/회외전[+2] | T20: 취급물 중량 >3kg (1) | U20: 1분이상 정적자세(1) | V20: 분당 4회이상 반복(1) | W20: =IF(X20<8,X20,7) -> 3 | X20: =B23+IF((J23+O23)>=2,2,J23+O23)+T23+MAX(U23,V23)+V24 -> 3
J21: 회내전[2] | O21: 회외전[2]
B23: =IF(OR(B22<=30,B22>=120),3,IF(OR(AND((B22>30),(B22<=60)),AND((B22>=100),(B22<120))),2,1)) -> 3 | J23: =IF(J22<60,0,IF(J22<80,1,2)) -> 0 | O23: =IF(O22<60,0,IF(O22<80,1,2)) -> 0 | T23: 0 | U23: 0 | V23: 0
B24: ◆ 부가점수 (각 +1) : | V24: =COUNTIF(X25:Z26,TRUE) -> 0
C25: [공구 1kg 이상] | J25: [공구 진동] | Q25: [손목회전시 강한 힘(중량물)] | X25: FALSE | Y25: FALSE | Z25: FALSE
C26: [팔꿈치 접촉 압박] | J26: [손으로 밀기/당기기] | Q26: [손 망치 작업] | X26: FALSE | Y26: FALSE | Z26: FALSE
A27: 어깨 /위팔 | B27: 자세[5] | T27: 힘[+1] | U27: 정적/반복[+1] | W27: 점수[7]
B28: 굴곡/신전[3] | J28: 외전/내전/외회전/내회전[+2] | T28: 취급물 중량 >3kg (1) | U28: 1분이상 정적자세(1) | V28: 분당 4회이상 반복(1) | W28: =IF(X28<8,X28,7) -> 1 | X28: =MAX(B31,D31,G31)+IF((J31+L31+N31+P31)>=2,2,J31+L31+N31+P31)+T31+MAX(U31,V31)+V32 -> 1
B29: 중립 [1] | D29: 굴곡 [3] | G29: 신전 [3] | J29: 외전[2] | L29: 내전[2] | N29: 외회전[2] | P29: 내회전[2]
B31: =IF(AND(B30>-5,B30<5),1,0) -> 1 | D31: =IF(D30<5,0,IF(D30<45,1,IF(D30<90,2,3))) -> 0 | G31: =IF(G30=0,0,IF(G30<20,2,3)) -> 0 | J31: =IF(J30<30,0,IF(J30<45,1,2)) -> 0 | L31: =IF(L30<10,0,IF(L30<30,1,2)) -> 0 | N31: =IF(N30<10,0,IF(N30<30,1,2)) -> 0 | P31: =IF(P30<30,0,IF(P30<45,1,2)) -> 0 | T31: 0 | U31: 0 | V31: 0
B32: ◆ 부가점수 (각 +1) : | V32: =COUNTIF(X33:Z36,TRUE) -> 0
C33: [공구 1kg 이상] | J33: [공구의 진동] | P33: [접촉 압박] | X33: FALSE | Y33: FALSE | Z33: FALSE
C34: [팔꿈치 과도한 신전] | J34: [어깨 치켜 올림] | P34: [허리 굽히고 팔 뻗기] | X34: FALSE | Y34: FALSE | Z34: FALSE
C35: [누운자세/엎드린자세] | J35: [어깨로 운반] | P35: [손을 이용해 중량물 들기/내리기] | X35: FALSE | Y35: FALSE | Z35: FALSE
C36: [손으로 중량물 운반] | J36: [손으로 중량물 밀기/당기기] | X36: FALSE | Y36: FALSE
A37: 목 | B37: 자세[5] | T37: 힘[+1] | U37: 정적/반복[+1] | W37: 점수[7]
B38: 굴곡/신전[3] | J38: 회전/측면기울임[+2] | T38: 머리 또는 목 부위 중량물 또는 힘이 작용 (1) | U38: 1분이상 정적자세(1) | V38: 분당 2회이상 반복(1) | W38: =IF(X38<8,X38,7) -> 1 | X38: =MAX(B41,D41,G41)+IF((J41+O41)>=2,2,J41+O41)+T41+MAX(U41,V41)+V42 -> 1
B39: 중립 [1] | D39: 굴곡 [3] | G39: 신전 [3] | J39: 회전 [2] | O39: 측면기울임 [2]
B41: =IF(B40<5,1,0) -> 1 | D41: =IF(D40<=5,0,IF(D40<20,1,IF(D40<45,2,3))) -> 0 | G41: =IF(G40=0,0,IF(G40<5,1,IF(G40<20,2,3))) -> 0 | J41: =IF(J40<20,0,IF(J40<45,1,2)) -> 0 | O41: =IF(O40<10,0,IF(O40<30,1,2)) -> 0 | T41: 0 | U41: 0 | V41: 0
B42: ◆ 부가점수 (각 +1) : | V42: =COUNTIF(X43:Y46,TRUE) -> 0
C43: [어깨위 손 올림] | O43: [허리 굽히고 팔 뻗기] | X43: FALSE | Y43: FALSE
C44: [움직임이 제한된 좁은 공간] | O44: [어깨로 운반하는 작업] | X44: FALSE | Y44: FALSE
...

Sheet 문서번호3(1)
H1: 문서번호 | L1: 2-1
A2: 근골격계 유해요인조사 관리카드(추가항목)
A3: 평가대상 | B3: 평가번호 | E3: 작업명 | H3: 요소작업
B4: =문서번호1!C8 -> 44935 | E4: =문서번호1!T8 -> CTB | H4: =문서번호1!B17 -> 작업1
A6: 입력 | C6: 팔이 무언가에 지탱되거나 기댄 상태인 경우 | N6: FALSE | P6: 상완자세 | Q6: 상완보정 | R6: 전완자세 | S6: 전완보정 | T6: 손목자세 | U6: 손목보정 | V6: 목자세 | W6: 목보정 | X6: 상체자세 | Y6: 상체보정 | AB6: RULA_A | AC6: RULA_B
C7: 다리와 발이 잘 지지되지 못하고, 체중분포도 균형을 이루지 못한 경우 | N7: FALSE | P7: {=IF(AND(('문서번호2(1)'!D30<=20),('문서번호2(1)'!G30<=20)),1,IF(OR(('문서번호2(1)'!G30>20), AND(('문서번호2(1)'!D30>20),('문서번호2(1)'!D30<=45))),2,IF(AND(('문서번호2(1)'!D30>45),('문서번호2(1)'!D30<=90)),3,IF(('문서번호2(1)'!D30>90),4,ER))))} -> 1 | Q7: =IF(('문서번호2(1)'!J30>30),1,0) -> 0 | R7: =IF(AND(('문서번호2(1)'!B22>60),('문서번호2(1)'!B22<100)),1,2) -> 2 | S7: =IF('문서번호2(1)'!J30>30,1,0) -> 0 | T7: =IF(AND(('문서번호2(1)'!B13=0),('문서번호2(1)'!F13=0)),1,IF(AND(('문서번호2(1)'!B13<15),('문서번호2(1)'!F13<15)),2,3)) -> 1 | U7: =IF(OR(('문서번호2(1)'!J13>5),('문서번호2(1)'!O13>10)),1,0) -> 0 | V7: =IF('문서번호2(1)'!D40=0,1,IF('문서번호2(1)'!D40<20,2,IF('문서번호2(1)'!D40<60,3,4))) -> 1 | W7: =IF('문서번호2(1)'!J40>10,1,0) -> 0 | X7: =IF('문서번호2(1)'!B50=0,1,IF('문서번호2(1)'!B50<20,2,IF('문서번호2(1)'!B50<60,3,4))) -> 1 | Y7: =IF('문서번호2(1)'!J50>10,1,0) -> 0 | AB7: {=LOOKUP(1,1/((B14=RULA_A!$A$2:$A$145)*(C14=RULA_A!B2:B145)*(D14=RULA_A!C2:C145)*(E14=RULA_A!D2:D145)),RULA_A!E2:E145)} -> 2 | AC7: {=LOOKUP(1,1/((H14=RULA_B!A2:A73)*(I14=RULA_B!B2:B73)*(J14=RULA_B!C2:C73)),RULA_B!D2:D73)} -> 1
C8: 급속하게 큰 범위로 자세를 변경하거나 발판이 불안정한 경우 | N8: FALSE | Q8: =IF(('문서번호2(1)'!Y34=TRUE),1,0) -> 0 | S8: =IF('문서번호2(1)'!L30>30,1,0) -> 0 | W8: =IF('문서번호2(1)'!O40>10,1,0) -> 0 | Y8: =IF('문서번호2(1)'!O50>10,1,0) -> 0 | AB8: =IF(AB7+F14+G14>12,12,AB7+F14+G14) -> 2 | AC8: =IF(AC7+K14+L14>12,12,AC7+K14+L14) -> 1
C9: 급격하게 힘을 사용하여 무리가 오는 경우 | N9: FALSE | Q9: =IF(N6=TRUE,-1,0) -> 0
B10: 무릎 | C10: 0~30도 구부리기 | N10: 0~30도 구부리기
B11: 손잡이 | C11: 양호 | N11: 30~60도 구부리기 | P11: 몸통굴곡 | Q11: 몸통신전 | R11: 목자세 | S11: 다리보정 | T11: 무게 | U11: 무게보정 | V11: 윗팔굴곡 | W11: 윗팔신전 | X11: 윗팔보정 | Y11: 행동점수1 | AA11: 행동점수2 | AB11: 행동점수3 | AC11: REBA_A | AD11: REBA_B
B12: 힘 | D12: kg | E12: 밀고당기기(kgf) | H12: 팔 | J12: 손 | L12: 손가락 | N12: 60도 이상 구부리기 | P12: =IF('문서번호2(1)'!B50=0,1,IF('문서번호2(1)'!B50<20,2,IF('문서번호2(1)'!B50<60,3,4))) -> 1 | Q12: =IF('문서번호2(1)'!F50=0,1,IF('문서번호2(1)'!F50<20,2,3)) -> 1 | R12: =IF(OR('문서번호2(1)'!D40>=20,'문서번호2(1)'!G40>=20),2,1) -> 1 | S12: =IF(C10="0~30도 구부리기",0,IF(C10="30~60도 구부리기",1,2)) -> 0 | T12: =IF(C12<5,0,IF(C12<10,1,2)) -> 0 | U12: =IF(N9=TRUE,1,0) -> 0 | V12: =IF('문서번호2(1)'!D30<20,1,IF('문서번호2(1)'!D30<45,2,IF('문서번호2(1)'!D30<90,3,4))) -> 1 | W12: =IF('문서번호2(1)'!G30<20,1,2) -> 1 | X12: =IF(('문서번호2(1)'!J31+'문서번호2(1)'!L31+'문서번호2(1)'!N31+'문서번호2(1)'!P31)>=1,1,0)+'문서번호3(1)'!Q8+'문서번호3(1)'!Q9 -> 0 | Y12: =IF('문서번호2(1)'!U14+'문서번호2(1)'!U23+'문서번호2(1)'!U31+'문서번호2(1)'!U41+'문서번호2(1)'!U51+'문서번호2(1)'!U62>0,1,0) -> 0 | AA12: =IF('문서번호2(1)'!V14+'문서번호2(1)'!V23+'문서번호2(1)'!V31+'문서번호2(1)'!V41+'문서번호2(1)'!V51>0,1,0) -> 0 | AB12: =IF(N8=TRUE,1,0) -> 0 | AC12: {=LOOKUP(1,1/((B17=REBA_A!A2:A61)*(C17=REBA_A!B2:B61)*(D17=REBA_A!C2:C61)),REBA_A!D2:D61)+E17} -> 1 | AD12: {=LOOKUP(1,1/((F17=REBA_B!A2:A61)*(G17=REBA_B!B2:B61)*(H17=REBA_B!C2:C61)),REBA_B!D2:D61)+I17} -> 1
B13: 상완 | C13: 전완 | D13: 손목 | E13: 비틀림 | F13: 근육 | G13: 힘 | H13: 목 | I13: 상체 | J13: 다리 | K13: 근육 | L13: 힘 | M13: 총점 | N13: 양호
A14: RULA | B14: =IF(P7+Q7+Q8+Q9>6,6,P7+Q7+Q8+Q9) -> 1 | C14: =IF(R7+S7+S8>3,3,R7+S7+S8) -> 2 | D14: =IF(T7+U7>4,4,T7+U7) -> 1 | E14: =IF(MAX('문서번호2(1)'!J22:S22)<=90,1,2) -> 1 | F14: =IF(('문서번호2(1)'!U14+'문서번호2(1)'!V14+'문서번호2(1)'!U23+'문서번호2(1)'!V23+'문서번호2(1)'!U31+'문서번호2(1)'!V31)>0,1,0) -> 0 | G14: =IF(C12<2,0,IF((C12>10),3,IF(AND((C12<=10),('문서번호2(1)'!U23+'문서번호2(1)'!V23+'문서번호2(1)'!U31+'문서번호2(1)'!V31>=1)),2,1))) -> 0 | H14: =IF(V7+W7+W8>6,6,V7+W7+W8) -> 1 | I14: =IF(X7+Y7+Y8>6,6,X7+Y7+Y8) -> 1 | J14: =IF(N7=TRUE,2,1) -> 1 | K14: =IF('문서번호2(1)'!U41+'문서번호2(1)'!V41+'문서번호2(1)'!U51+'문서번호2(1)'!V51+'문서번호2(1)'!U62>0,1,0) -> 0 | L14: =G14 -> 0 | M14: =INDEX('C+D'!B2:M13,MATCH(AB8,'C+D'!A2:A13,0),MATCH(AC8,'C+D'!B1:M1,0)) -> 2 | N14: 적당
B15: ■ 부하수준(1~4) : | E15: =IF(M14<3,1,IF(M14<5,2,IF(M14<7,3,4))) -> 1 | H15: =IF(E15=1,"안전",IF(E15=2,"보통",IF(E15=3,"위험","고위험"))) -> 안전 | N15: 불충분
B16: 몸통 | C16: 목 | D16: 다리 | E16: 무게 | F16: 윗팔 | G16: 아래팔 | H16: 손목 | I16: 손잡이 | J16: 행동점수 | L16: 총점 | N16: 좋지 않음
A17: REBA | B17: =MAX(P12:Q12)+MAX(Y7:Y8) -> 1 | C17: =R12+MAX(W7:W8) -> 1 | D17: =J14+S12 -> 1 | E17: =T12+U12 -> 0 | F17: =MAX(V12:W12)+X12 -> 1 | G17: =R7 -> 2 | H17: =IF(OR('문서번호2(1)'!B13>=15,'문서번호2(1)'!F13>=15),2,1)+U7 -> 1 | I17: =IF(C11=N13,0,IF(C11=N14,1,IF(C11=N15,2,3))) -> 0 | J17: =Y12+AA12+AB12 -> 0 | L17: =INDEX('A+B'!B2:M13,MATCH(AC12,'A+B'!A2:A13,0),MATCH(AD12,'A+B'!B1:M1,0))+J17 -> 1
B18: ■ 조치단계(0~4) : | E18: =IF(L17<2,0,IF(L17<4,1,IF(L17<8,2,IF(L17<11,3,4)))) -> 0 | H18: =IF(OR(E18=1,E18=0),"안전",IF(E18=2,"보통",IF(E18=3,"위험","고위험"))) -> 안전
A19: Push-Pull | B19: 팔 | C19: =IF(I12=0,"없음",IF(I12<9,"안전",IF(I12<14.5,"보통",IF(I12<23,"위험","고위험")))) -> 없음 | F19: 손 | G19: =IF(K12=0,"없음",IF(K12<5,"안전","위험")) -> 없음 | J19: 손가락 | K19: =IF(M12=0,"없음",IF(M12<1,"안전","위험")) -> 없음
T33: TRUE

Sheet 문서번호2(2)
T1: 문서번호 | V1: 2
A2: 근골격계 유해요인조사 관리카드(2/3)
A3: 평가 대상 | B3: 부서명 | J3: 작업명 | T3: 요소작업명
B4: =문서번호1!K8 -> 생산1팀 | J4: =문서번호1!T8 -> CTB | T4: =문서번호1!B18 -> 작업2
A5: 작업 특성 | B5: ◆ 공구무게 | H5: ( | K5: )kg
B6: ◆ 중량물 무게 | H6: ( | K6: )kg | L6: × | M6: 빈도 1일 | P6: ( | S6: ) | T6: 회
B7: ◆ 밀고당기기 | H7: ( | K7: )kgf | L7: × | M7: 빈도 1일 | P7: ( | S7: ) | T7: 회
B8: ◆ 전신진동발생원 | H8: ( | K8: ) | M8: 1일 평균 | P8: ( | S8: ) | T8: 시간
A9: 위험 요인 | B9: 위험요인 노출특성 (신체 부위별 자세/힘의사용/정적/반복/진동/압박/충격 등 부가점수 포함 최고 점수 : 7점)
A10: 손/손목 | B10: 자세[5] | T10: 힘[+1] | U10: 정적/반복[+1] | W10: 점수[7]
B11: 굴곡/신전[3] | J11: 외전/내전[+2] | T11: 취급물 중량 손가락>1kg 또는 손>2kg(1) | U11: 1분이상 정적자세(1) | V11: 분당 4회이상 반복(1) | W11: =IF(X11<8,X11,7) -> 1 | X11: =MAX(B14,F14)+IF((J14+O14)>=2,2,J14+O14)+T14+MAX(U14,V14)+V15 -> 1
B12: 굴곡 | F12: 신전 | J12: 내전[2] | O12: 외전[2]
B14: =IF(B13<15,1,IF(B13<45,2,3)) -> 1 | F14: =IF(F13<15,1,IF(F13<45,2,3)) -> 1 | J14: =IF(J13<15,0,IF(J13<30,1,2)) -> 0 | O14: =IF(O13<15,0,IF(O13<30,1,2)) -> 0 | T14: 0 | U14: 0 | V14: 0
B15: ◆ 부가점수 (각 +1) : | V15: =COUNTIF(X16:Z18,TRUE) -> 0
C16: [공구 1kg 이상] | J16: [공구 2kg 이상] | Q16: [공구진동] | X16: FALSE | Y16: FALSE | Z16: FALSE
C17: [손가락 쥐기/집기] | J17: [과도한 손가락 신전] | Q17: [접촉 압박/충격] | X17: FALSE | Y17: FALSE | Z17: FALSE
C18: [미끄러운 장갑 착용] | J18: [손을 망치처럼 사용] | X18: FALSE | Y18: FALSE
A19: 팔꿈치 /아래팔 | B19: 자세[5] | T19: 힘[+1] | U19: 정적/반복[+1] | W19: 점수[7]
B20: 굴곡[3] | J20: 회내전/회외전[+2] | T20: 취급물 중량 >3kg (1) | U20: 1분이상 정적자세(1) | V20: 분당 4회이상 반복(1) | W20: =IF(X20<8,X20,7) -> 3 | X20: =B23+IF((J23+O23)>=2,2,J23+O23)+T23+MAX(U23,V23)+V24 -> 3
J21: 회내전[2] | O21: 회외전[2]
B23: =IF(OR(B22<=30,B22>=120),3,IF(OR(AND((B22>30),(B22<=60)),AND((B22>=100),(B22<120))),2,1)) -> 3 | J23: =IF(J22<60,0,IF(J22<80,1,2)) -> 0 | O23: =IF(O22<60,0,IF(O22<80,1,2)) -> 0 | T23: 0 | U23: 0 | V23: 0
B24: ◆ 부가점수 (각 +1) : | V24: =COUNTIF(X25:Z26,TRUE) -> 0
C25: [공구 1kg 이상] | J25: [공구 진동] | Q25: [손목회전시 강한 힘(중량물)] | X25: FALSE | Y25: FALSE | Z25: FALSE
C26: [팔꿈치 접촉 압박] | J26: [손으로 밀기/당기기] | Q26: [손 망치 작업] | X26: FALSE | Y26: FALSE | Z26: FALSE
A27: 어깨 /위팔 | B27: 자세[5] | T27: 힘[+1] | U27: 정적/반복[+1] | W27: 점수[7]
B28: 굴곡/신전[3] | J28: 외전/내전/외회전/내회전[+2] | T28: 취급물 중량 >3kg (1) | U28: 1분이상 정적자세(1) | V28: 분당 4회이상 반복(1) | W28: =IF(X28<8,X28,7) -> 1 | X28: =MAX(B31,D31,G31)+IF((J31+L31+N31+P31)>=2,2,J31+L31+N31+P31)+T31+MAX(U31,V31)+V32 -> 1
B29: 중립 [1] | D29: 굴곡 [3] | G29: 신전 [3] | J29: 외전[2] | L29: 내전[2] | N29: 외회전[2] | P29: 내회전[2]
B31: =IF(AND(B30>-5,B30<5),1,0) -> 1 | D31: =IF(D30<5,0,IF(D30<45,1,IF(D30<90,2,3))) -> 0 | G31: =IF(G30=0,0,IF(G30<20,2,3)) -> 0 | J31: =IF(J30<30,0,IF(J30<45,1,2)) -> 0 | L31: =IF(L30<10,0,IF(L30<30,1,2)) -> 0 | N31: =IF(N30<10,0,IF(N30<30,1,2)) -> 0 | P31: =IF(P30<30,0,IF(P30<45,1,2)) -> 0 | T31: 0 | U31: 0 | V31: 0
B32: ◆ 부가점수 (각 +1) : | V32: =COUNTIF(X33:Z36,TRUE) -> 0
C33: [공구 1kg 이상] | J33: [공구의 진동] | P33: [접촉 압박] | X33: FALSE | Y33: FALSE | Z33: FALSE
C34: [팔꿈치 과도한 신전] | J34: [어깨 치켜 올림] | P34: [허리 굽히고 팔 뻗기] | X34: FALSE | Y34: FALSE | Z34: FALSE
C35: [누운자세/엎드린자세] | J35: [어깨로 운반] | P35: [손을 이용해 중량물 들기/내리기] | X35: FALSE | Y35: FALSE | Z35: FALSE
C36: [손으로 중량물 운반] | J36: [손으로 중량물 밀기/당기기] | X36: FALSE | Y36: FALSE
A37: 목 | B37: 자세[5] | T37: 힘[+1] | U37: 정적/반복[+1] | W37: 점수[7]
B38: 굴곡/신전[3] | J38: 회전/측면기울임[+2] | T38: 머리 또는 목 부위 중량물 또는 힘이 작용 (1) | U38: 1분이상 정적자세(1) | V38: 분당 2회이상 반복(1) | W38: =IF(X38<8,X38,7) -> 1 | X38: =MAX(B41,D41,G41)+IF((J41+O41)>=2,2,J41+O41)+T41+MAX(U41,V41)+V42 -> 1
B39: 중립 [1] | D39: 굴곡 [3] | G39: 신전 [3] | J39: 회전 [2] | O39: 측면기울임 [2]
B41: =IF(B40<5,1,0) -> 1 | D41: =IF(D40<=5,0,IF(D40<20,1,IF(D40<45,2,3))) -> 0 | G41: =IF(G40=0,0,IF(G40<5,1,IF(G40<20,2,3))) -> 0 | J41: =IF(J40<20,0,IF(J40<45,1,2)) -> 0 | O41: =IF(O40<10,0,IF(O40<30,1,2)) -> 0 | T41: 0 | U41: 0 | V41: 0
B42: ◆ 부가점수 (각 +1) : | V42: =COUNTIF(X43:Y46,TRUE) -> 0
C43: [어깨위 손 올림] | O43: [허리 굽히고 팔 뻗기] | X43: FALSE | Y43: FALSE
C44: [움직임이 제한된 좁은 공간] | O44: [어깨로 운반하는 작업] | X44: FALSE | Y44: FALSE
...

Sheet 문서번호3(2)
H1: 문서번호 | L1: 2-1
A2: 근골격계 유해요인조사 관리카드(추가항목)
A3: 평가대상 | B3: 평가번호 | E3: 작업명 | H3: 요소작업
B4: =문서번호1!C8 -> 44935 | E4: =문서번호1!T8 -> CTB | H4: =문서번호1!B18 -> 작업2
A6: 입력 | C6: 팔이 무언가에 지탱되거나 기댄 상태인 경우 | N6: FALSE | P6: 상완자세 | Q6: 상완보정 | R6: 전완자세 | S6: 전완보정 | T6: 손목자세 | U6: 손목보정 | V6: 목자세 | W6: 목보정 | X6: 상체자세 | Y6: 상체보정 | AB6: RULA_A | AC6: RULA_B
C7: 다리와 발이 잘 지지되지 못하고, 체중분포도 균형을 이루지 못한 경우 | N7: FALSE | P7: {=IF(AND(('문서번호2(2)'!D30<=20),('문서번호2(2)'!G30<=20)),1,IF(OR(('문서번호2(2)'!G30>20), AND(('문서번호2(2)'!D30>20),('문서번호2(2)'!D30<=45))),2,IF(AND(('문서번호2(2)'!D30>45),('문서번호2(2)'!D30<=90)),3,IF(('문서번호2(2)'!D30>90),4,ER))))} -> 1 | Q7: =IF(('문서번호2(2)'!J30>30),1,0) -> 0 | R7: =IF(AND(('문서번호2(2)'!B22>60),('문서번호2(2)'!B22<100)),1,2) -> 2 | S7: =IF('문서번호2(2)'!J30>30,1,0) -> 0 | T7: =IF(AND(('문서번호2(2)'!B13=0),('문서번호2(2)'!F13=0)),1,IF(AND(('문서번호2(2)'!B13<15),('문서번호2(2)'!F13<15)),2,3)) -> 1 | U7: =IF(OR(('문서번호2(2)'!J13>5),('문서번호2(2)'!O13>10)),1,0) -> 0 | V7: =IF('문서번호2(2)'!D40=0,1,IF('문서번호2(2)'!D40<20,2,IF('문서번호2(2)'!D40<60,3,4))) -> 1 | W7: =IF('문서번호2(2)'!J40>10,1,0) -> 0 | X7: =IF('문서번호2(2)'!B50=0,1,IF('문서번호2(2)'!B50<20,2,IF('문서번호2(2)'!B50<60,3,4))) -> 1 | Y7: =IF('문서번호2(2)'!J50>10,1,0) -> 0 | AB7: {=LOOKUP(1,1/((B14=RULA_A!$A$2:$A$145)*(C14=RULA_A!B2:B145)*(D14=RULA_A!C2:C145)*(E14=RULA_A!D2:D145)),RULA_A!E2:E145)} -> 2 | AC7: {=LOOKUP(1,1/((H14=RULA_B!A2:A73)*(I14=RULA_B!B2:B73)*(J14=RULA_B!C2:C73)),RULA_B!D2:D73)} -> 1
C8: 급속하게 큰 범위로 자세를 변경하거나 발판이 불안정한 경우 | N8: FALSE | Q8: =IF(('문서번호2(2)'!Y34=TRUE),1,0) -> 0 | S8: =IF('문서번호2(2)'!L30>30,1,0) -> 0 | W8: =IF('문서번호2(2)'!O40>10,1,0) -> 0 | Y8: =IF('문서번호2(2)'!O50>10,1,0) -> 0 | AB8: =IF(AB7+F14+G14>12,12,AB7+F14+G14) -> 2 | AC8: =IF(AC7+K14+L14>12,12,AC7+K14+L14) -> 1
C9: 급격하게 힘을 사용하여 무리가 오는 경우 | N9: FALSE | Q9: =IF(N6=TRUE,-1,0) -> 0
B10: 무릎 | C10: 0~30도 구부리기 | N10: 0~30도 구부리기
B11: 손잡이 | C11: 양호 | N11: 30~60도 구부리기 | P11: 몸통굴곡 | Q11: 몸통신전 | R11: 목자세 | S11: 다리보정 | T11: 무게 | U11: 무게보정 | V11: 윗팔굴곡 | W11: 윗팔신전 | X11: 윗팔보정 | Y11: 행동점수1 | AA11: 행동점수2 | AB11: 행동점수3 | AC11: REBA_A | AD11: REBA_B
B12: 힘 | D12: kg | E12: 밀고당기기(kgf) | H12: 팔 | J12: 손 | L12: 손가락 | N12: 60도 이상 구부리기 | P12: =IF('문서번호2(2)'!B50=0,1,IF('문서번호2(2)'!B50<20,2,IF('문서번호2(2)'!B50<60,3,4))) -> 1 | Q12: =IF('문서번호2(2)'!F50=0,1,IF('문서번호2(2)'!F50<20,2,3)) -> 1 | R12: =IF(OR('문서번호2(2)'!D40>=20,'문서번호2(2)'!G40>=20),2,1) -> 1 | S12: =IF(C10="0~30도 구부리기",0,IF(C10="30~60도 구부리기",1,2)) -> 0 | T12: =IF(C12<5,0,IF(C12<10,1,2)) -> 0 | U12: =IF(N9=TRUE,1,0) -> 0 | V12: =IF('문서번호2(2)'!D30<20,1,IF('문서번호2(2)'!D30<45,2,IF('문서번호2(2)'!D30<90,3,4))) -> 1 | W12: =IF('문서번호2(2)'!G30<20,1,2) -> 1 | X12: =IF(('문서번호2(2)'!J31+'문서번호2(2)'!L31+'문서번호2(2)'!N31+'문서번호2(2)'!P31)>=1,1,0)+'문서번호3(2)'!Q8+'문서번호3(2)'!Q9 -> 0 | Y12: =IF('문서번호2(2)'!U14+'문서번호2(2)'!U23+'문서번호2(2)'!U31+'문서번호2(2)'!U41+'문서번호2(2)'!U51+'문서번호2(2)'!U62>0,1,0) -> 0 | AA12: =IF('문서번호2(2)'!V14+'문서번호2(2)'!V23+'문서번호2(2)'!V31+'문서번호2(2)'!V41+'문서번호2(2)'!V51>0,1,0) -> 0 | AB12: =IF(N8=TRUE,1,0) -> 0 | AC12: {=LOOKUP(1,1/((B17=REBA_A!A2:A61)*(C17=REBA_A!B2:B61)*(D17=REBA_A!C2:C61)),REBA_A!D2:D61)+E17} -> 1 | AD12: {=LOOKUP(1,1/((F17=REBA_B!A2:A61)*(G17=REBA_B!B2:B61)*(H17=REBA_B!C2:C61)),REBA_B!D2:D61)+I17} -> 1
B13: 상완 | C13: 전완 | D13: 손목 | E13: 비틀림 | F13: 근육 | G13: 힘 | H13: 목 | I13: 상체 | J13: 다리 | K13: 근육 | L13: 힘 | M13: 총점 | N13: 양호
A14: RULA | B14: =IF(P7+Q7+Q8+Q9>6,6,P7+Q7+Q8+Q9) -> 1 | C14: =IF(R7+S7+S8>3,3,R7+S7+S8) -> 2 | D14: =IF(T7+U7>4,4,T7+U7) -> 1 | E14: =IF(MAX('문서번호2(2)'!J22:S22)<=90,1,2) -> 1 | F14: =IF(('문서번호2(2)'!U14+'문서번호2(2)'!V14+'문서번호2(2)'!U23+'문서번호2(2)'!V23+'문서번호2(2)'!U31+'문서번호2(2)'!V31)>0,1,0) -> 0 | G14: =IF(C12<2,0,IF((C12>10),3,IF(AND((C12<=10),('문서번호2(2)'!U23+'문서번호2(2)'!V23+'문서번호2(2)'!U31+'문서번호2(2)'!V31>=1)),2,1))) -> 0 | H14: =IF(V7+W7+W8>6,6,V7+W7+W8) -> 1 | I14: =IF(X7+Y7+Y8>6,6,X7+Y7+Y8) -> 1 | J14: =IF(N7=TRUE,2,1) -> 1 | K14: =IF('문서번호2(2)'!U41+'문서번호2(2)'!V41+'문서번호2(2)'!U51+'문서번호2(2)'!V51+'문서번호2(2)'!U62>0,1,0) -> 0 | L14: =G14 -> 0 | M14: =INDEX('C+D'!B2:M13,MATCH(AB8,'C+D'!A2:A13,0),MATCH(AC8,'C+D'!B1:M1,0)) -> 2 | N14: 적당
B15: ■ 부하수준(1~4) : | E15: =IF(M14<3,1,IF(M14<5,2,IF(M14<7,3,4))) -> 1 | H15: =IF(E15=1,"안전",IF(E15=2,"보통",IF(E15=3,"위험","고위험"))) -> 안전 | N15: 불충분
B16: 몸통 | C16: 목 | D16: 다리 | E16: 무게 | F16: 윗팔 | G16: 아래팔 | H16: 손목 | I16: 손잡이 | J16: 행동점수 | L16: 총점 | N16: 좋지 않음
A17: REBA | B17: =MAX(P12:Q12)+MAX(Y7:Y8) -> 1 | C17: =R12+MAX(W7:W8) -> 1 | D17: =J14+S12 -> 1 | E17: =T12+U12 -> 0 | F17: =MAX(V12:W12)+X12 -> 1 | G17: =R7 -> 2 | H17: =IF(OR('문서번호2(2)'!B13>=15,'문서번호2(2)'!F13>=15),2,1)+U7 -> 1 | I17: =IF(C11=N13,0,IF(C11=N14,1,IF(C11=N15,2,3))) -> 0 | J17: =Y12+AA12+AB12 -> 0 | L17: =INDEX('A+B'!B2:M13,MATCH(AC12,'A+B'!A2:A13,0),MATCH(AD12,'A+B'!B1:M1,0))+J17 -> 1
B18: ■ 조치단계(0~4) : | E18: =IF(L17<2,0,IF(L17<4,1,IF(L17<8,2,IF(L17<11,3,4)))) -> 0 | H18: =IF(OR(E18=1,E18=0),"안전",IF(E18=2,"보통",IF(E18=3,"위험","고위험"))) -> 안전
A19: Push-Pull | B19: 팔 | C19: =IF(I12=0,"없음",IF(I12<9,"안전",IF(I12<14.5,"보통",IF(I12<23,"위험","고위험")))) -> 없음 | F19: 손 | G19: =IF(K12=0,"없음",IF(K12<5,"안전","위험")) -> 없음 | J19: 손가락 | K19: =IF(M12=0,"없음",IF(M12<1,"안전","위험")) -> 없음
T33: TRUE

Sheet 문서번호3
H1: 문서번호 | L1: 3
A2: 근골격계 유해요인조사 관리카드(3/3)
A3: 평가대상 | B3: 평가번호 | E3: 부서명 | H3: 작업명
B4: =문서번호1!C8 -> 44935 | E4: =문서번호1!K8 -> 생산1팀 | H4: =문서번호1!T8 -> CTB
A6: =문서번호1!B17 -> 작업1 | B6: 손/손목 | D6: 팔/팔꿈치 | F6: 어깨/위팔 | H6: 목 | J6: 허리/고관절 | L6: 무릎/발목
B7: ='문서번호2(1)'!W11 -> 1 | D7: ='문서번호2(1)'!W20 -> 3 | F7: ='문서번호2(1)'!W28 -> 1 | H7: ='문서번호2(1)'!W38 -> 1 | J7: ='문서번호2(1)'!W48 -> 1 | L7: ='문서번호2(1)'!W59 -> 0
B8: ■ 평가결과 :
A10: 추가평가 | B10: RULA | C10: ='문서번호3(1)'!H15 -> 안전 | F10: 총점 | G10: ='문서번호3(1)'!M14 -> 2 | H10: REBA | I10: ='문서번호3(1)'!H18 -> 안전 | L10: 총점 | M10: ='문서번호3(1)'!L17 -> 1
A11: Push-Pull | B11: 팔 | C11: ='문서번호3(1)'!C19 -> 없음 | E11: ='문서번호3(1)'!I12 -> 0 | F11: 손 | G11: ='문서번호3(1)'!G19 -> 없음 | I11: ='문서번호3(1)'!K12 -> 0 | J11: 손가락 | K11: ='문서번호3(1)'!K19 -> 없음 | M11: ='문서번호3(1)'!M12 -> 0
A12: =문서번호1!B18 -> 작업2 | B12: 손/손목 | D12: 팔/팔꿈치 | F12: 어깨/위팔 | H12: 목 | J12: 허리/고관절 | L12: 무릎/발목
B13: ='문서번호2(2)'!W11 -> 1 | D13: ='문서번호2(2)'!W20 -> 3 | F13: ='문서번호2(2)'!W28 -> 1 | H13: ='문서번호2(2)'!W38 -> 1 | J13: ='문서번호2(2)'!W48 -> 1 | L13: ='문서번호2(2)'!W59 -> 0
B14: ■ 평가결과 :
A16: 추가평가 | B16: RULA | C16: ='문서번호3(2)'!H15 -> 안전 | F16: 총점 | G16: ='문서번호3(2)'!M14 -> 2 | H16: REBA | I16: ='문서번호3(2)'!H18 -> 안전 | L16: 총점 | M16: ='문서번호3(2)'!L17 -> 1
A17: Push-Pull | B17: 팔 | C17: ='문서번호3(2)'!C19 -> 없음 | E17: ='문서번호3(2)'!I12 -> 0 | F17: 손 | G17: ='문서번호3(2)'!G19 -> 없음 | I17: ='문서번호3(2)'!K12 -> 0 | J17: 손가락 | K17: ='문서번호3(2)'!K19 -> 없음 | M17: ='문서번호3(2)'!M12 -> 0
A18: 관리 단계 : ☐상[7점] / ☐중상[5-6점] / ☐중[3-4점] / ☐하[1-2점]
A19: ※ 「중상」단계 이상인 경우, 예방을 위해 우선 개선조치를 취해야 함.
A21: 문서번호 | B21: 주요 문제점 | G21: 개선 검토 방향(안) | L21: 수집경로
A28: 참조

Sheet RULA_A
A1: 상완 | B1: 전완 | C1: 손목 | D1: 비틀림 | E1: 점수A
A2: 1 | B2: 1 | C2: 1 | D2: 1 | E2: 1
A3: 1 | B3: 1 | C3: 1 | D3: 2 | E3: 2
A4: 1 | B4: 1 | C4: 2 | D4: 1 | E4: 2
A5: 1 | B5: 1 | C5: 2 | D5: 2 | E5: 2
A6: 1 | B6: 1 | C6: 3 | D6: 1 | E6: 2
A7: 1 | B7: 1 | C7: 3 | D7: 2 | E7: 3
A8: 1 | B8: 1 | C8: 4 | D8: 1 | E8: 3
A9: 1 | B9: 1 | C9: 4 | D9: 2 | E9: 3
A10: 1 | B10: 2 | C10: 1 | D10: 1 | E10: 2
A11: 1 | B11: 2 | C11: 1 | D11: 2 | E11: 2
A12: 1 | B12: 2 | C12: 2 | D12: 1 | E12: 2
A13: 1 | B13: 2 | C13: 2 | D13: 2 | E13: 2
... A145: 6 | B145: 3 | C145: 4 | D145: 2 | E145: 9

Sheet RULA_B
A1: 목 | B1: 상체 | C1: 다리 | D1: 점수B
A2: 1 | B2: 1 | C2: 1 | D2: 1
A3: 1 | B3: 1 | C3: 2 | D3: 3
A4: 1 | B4: 2 | C4: 1 | D4: 2
A5: 1 | B5: 2 | C5: 2 | D5: 3
A6: 1 | B6: 3 | C6: 1 | D6: 3
A7: 1 | B7: 3 | C7: 2 | D7: 4
A8: 1 | B8: 4 | C8: 1 | D8: 5
A9: 1 | B9: 4 | C9: 2 | D9: 5
A10: 1 | B10: 5 | C10: 1 | D10: 6
A11: 1 | B11: 5 | C11: 2 | D11: 6
A12: 1 | B12: 6 | C12: 1 | D12: 7
A13: 1 | B13: 6 | C13: 2 | D13: 7
... A73: 6 | B73: 6 | C73: 2 | D73: 9

Sheet C+D
B1: 1 | C1: 2 | D1: 3 | E1: 4 | F1: 5 | G1: 6 | H1: 7 | I1: 8 | J1: 9 | K1: 10 | L1: 11 | M1: 12
A2: 1 | B2: 1 | C2: 2 | D2: 3 | E2: 3 | F2: 4 | G2: 5 | H2: 5 | I2: 5 | J2: 5 | K2: 5 | L2: 5 | M2: 5
A3: 2 | B3: 2 | C3: 2 | D3: 3 | E3: 4 | F3: 4 | G3: 5 | H3: 5 | I3: 5 | J3: 5 | K3: 5 | L3: 5 | M3: 5
A4: 3 | B4: 3 | C4: 3 | D4: 3 | E4: 4 | F4: 4 | G4: 5 | H4: 6 | I4: 6 | J4: 6 | K4: 6 | L4: 6 | M4: 6
A5: 4 | B5: 3 | C5: 3 | D5: 3 | E5: 4 | F5: 5 | G5: 6 | H5: 6 | I5: 6 | J5: 6 | K5: 6 | L5: 6 | M5: 6
A6: 5 | B6: 4 | C6: 4 | D6: 4 | E6: 5 | F6: 6 | G6: 7 | H6: 7 | I6: 7 | J6: 7 | K6: 7 | L6: 7 | M6: 7
A7: 6 | B7: 4 | C7: 4 | D7: 5 | E7: 6 | F7: 6 | G7: 7 | H7: 7 | I7: 7 | J7: 7 | K7: 7 | L7: 7 | M7: 7
A8: 7 | B8: 5 | C8: 5 | D8: 6 | E8: 6 | F8: 7 | G8: 7 | H8: 7 | I8: 7 | J8: 7 | K8: 7 | L8: 7 | M8: 7
A9: 8 | B9: 5 | C9: 5 | D9: 6 | E9: 7 | F9: 7 | G9: 7 | H9: 7 | I9: 7 | J9: 7 | K9: 7 | L9: 7 | M9: 7
A10: 9 | B10: 5 | C10: 5 | D10: 6 | E10: 7 | F10: 7 | G10: 7 | H10: 7 | I10: 7 | J10: 7 | K10: 7 | L10: 7 | M10: 7
A11: 10 | B11: 5 | C11: 5 | D11: 6 | E11: 7 | F11: 7 | G11: 7 | H11: 7 | I11: 7 | J11: 7 | K11: 7 | L11: 7 | M11: 7
A12: 11 | B12: 5 | C12: 5 | D12: 6 | E12: 7 | F12: 7 | G12: 7 | H12: 7 | I12: 7 | J12: 7 | K12: 7 | L12: 7 | M12: 7
A13: 12 | B13: 5 | C13: 5 | D13: 6 | E13: 7 | F13: 7 | G13: 7 | H13: 7 | I13: 7 | J13: 7 | K13: 7 | L13: 7 | M13: 7

Sheet REBA_A
A1: 몸통 | B1: 목 | C1: 다리 | D1: 점수A
A2: 1 | B2: 1 | C2: 1 | D2: 1
A3: 1 | B3: 2 | C3: 1 | D3: 1
A4: 2 | B4: 1 | C4: 1 | D4: 2
A5: 1 | B5: 1 | C5: 2 | D5: 2
A6: 3 | B6: 1 | C6: 1 | D6: 2
A7: 1 | B7: 2 | C7: 2 | D7: 2
A8: 4 | B8: 1 | C8: 1 | D8: 3
A9: 2 | B9: 1 | C9: 2 | D9: 3
A10: 1 | B10: 1 | C10: 3 | D10: 3
A11: 2 | B11: 2 | C11: 1 | D11: 3
A12: 1 | B12: 2 | C12: 3 | D12: 3
A13: 1 | B13: 3 | C13: 1 | D13: 3
... A61: 5 | B61: 3 | C61: 4 | D61: 9

Sheet REBA_B
A1: 윗팔 | B1: 아래팔 | C1: 손목 | D1: 점수B
A2: 1 | B2: 1 | C2: 1 | D2: 1
A3: 2 | B3: 1 | C3: 1 | D3: 1
A4: 1 | B4: 2 | C4: 1 | D4: 1
A5: 1 | B5: 1 | C5: 2 | D5: 2
A6: 2 | B6: 1 | C6: 2 | D6: 2
A7: 1 | B7: 1 | C7: 3 | D7: 2
A8: 2 | B8: 2 | C8: 1 | D8: 2
A9: 1 | B9: 2 | C9: 2 | D9: 2
A10: 3 | B10: 1 | C10: 1 | D10: 3
A11: 2 | B11: 1 | C11: 3 | D11: 3
A12: 2 | B12: 2 | C12: 2 | D12: 3
A13: 1 | B13: 2 | C13: 3 | D13: 3
... A37: 6 | B37: 2 | C37: 3 | D37: 9

Sheet A+B
B1: 1 | C1: 2 | D1: 3 | E1: 4 | F1: 5 | G1: 6 | H1: 7 | I1: 8 | J1: 9 | K1: 10 | L1: 11 | M1: 12
A2: 1 | B2: 1 | C2: 1 | D2: 1 | E2: 2 | F2: 3 | G2: 3 | H2: 4 | I2: 5 | J2: 6 | K2: 7 | L2: 7 | M2: 7
A3: 2 | B3: 1 | C3: 2 | D3: 2 | E3: 3 | F3: 4 | G3: 4 | H3: 5 | I3: 6 | J3: 6 | K3: 7 | L3: 7 | M3: 8
A4: 3 | B4: 2 | C4: 3 | D4: 3 | E4: 3 | F4: 4 | G4: 5 | H4: 6 | I4: 7 | J4: 7 | K4: 8 | L4: 8 | M4: 8
A5: 4 | B5: 3 | C5: 4 | D5: 4 | E5: 4 | F5: 5 | G5: 6 | H5: 7 | I5: 8 | J5: 8 | K5: 9 | L5: 9 | M5: 9
A6: 5 | B6: 4 | C6: 4 | D6: 4 | E6: 5 | F6: 6 | G6: 7 | H6: 8 | I6: 8 | J6: 9 | K6: 9 | L6: 9 | M6: 9
A7: 6 | B7: 6 | C7: 6 | D7: 6 | E7: 7 | F7: 8 | G7: 8 | H7: 9 | I7: 9 | J7: 10 | K7: 10 | L7: 10 | M7: 10
A8: 7 | B8: 7 | C8: 7 | D8: 7 | E8: 8 | F8: 9 | G8: 9 | H8: 9 | I8: 10 | J8: 10 | K8: 11 | L8: 11 | M8: 11
A9: 8 | B9: 8 | C9: 8 | D9: 8 | E9: 9 | F9: 10 | G9: 10 | H9: 10 | I9: 10 | J9: 10 | K9: 11 | L9: 11 | M9: 11
A10: 9 | B10: 9 | C10: 9 | D10: 9 | E10: 10 | F10: 10 | G10: 10 | H10: 11 | I10: 11 | J10: 11 | K10: 12 | L10: 12 | M10: 12
A11: 10 | B11: 10 | C11: 10 | D11: 10 | E11: 11 | F11: 11 | G11: 11 | H11: 11 | I11: 12 | J11: 12 | K11: 12 | L11: 12 | M11: 12
A12: 11 | B12: 11 | C12: 11 | D12: 11 | E12: 11 | F12: 12 | G12: 12 | H12: 12 | I12: 12 | J12: 12 | K12: 12 | L12: 12 | M12: 12
A13: 12 | B13: 12 | C13: 12 | D13: 12 | E13: 12 | F13: 12 | G13: 12 | H13: 12 | I13: 12 | J13: 12 | K13: 12 | L13: 12 | M13: 12
